<?xml version="1.0" encoding="UTF-8"?>
<testng-results skipped="0" failed="3" ignored="0" total="9" passed="6">
  <reporter-output>
  </reporter-output>
  <suite name="Default suite" duration-ms="927" started-at="2021-05-07T14:29:07 IST" finished-at="2021-05-07T14:29:08 IST">
    <groups>
    </groups>
    <test name="Default test" duration-ms="927" started-at="2021-05-07T14:29:07 IST" finished-at="2021-05-07T14:29:08 IST">
      <class name="com.csscorp.bankapp.test.BankAppTest">
        <test-method status="PASS" signature="accountCreationTest(java.lang.String, double)[pri:0, instance:com.csscorp.bankapp.test.BankAppTest@32709393]" name="accountCreationTest" duration-ms="11" started-at="2021-05-07T14:29:07 IST" data-provider="accountsTestData" finished-at="2021-05-07T14:29:07 IST">
          <params>
            <param index="0">
              <value>
                <![CDATA[charles]]>
              </value>
            </param>
            <param index="1">
              <value>
                <![CDATA[2000.0]]>
              </value>
            </param>
          </params>
          <reporter-output>
          </reporter-output>
        </test-method> <!-- accountCreationTest -->
        <test-method status="PASS" signature="accountCreationTest(java.lang.String, double)[pri:0, instance:com.csscorp.bankapp.test.BankAppTest@32709393]" name="accountCreationTest" duration-ms="1" started-at="2021-05-07T14:29:07 IST" data-provider="accountsTestData" finished-at="2021-05-07T14:29:07 IST">
          <params>
            <param index="0">
              <value>
                <![CDATA[John]]>
              </value>
            </param>
            <param index="1">
              <value>
                <![CDATA[5000.0]]>
              </value>
            </param>
          </params>
          <reporter-output>
          </reporter-output>
        </test-method> <!-- accountCreationTest -->
        <test-method status="PASS" signature="accountCreationTest(java.lang.String, double)[pri:0, instance:com.csscorp.bankapp.test.BankAppTest@32709393]" name="accountCreationTest" duration-ms="16" started-at="2021-05-07T14:29:07 IST" data-provider="accountsTestData" finished-at="2021-05-07T14:29:07 IST">
          <params>
            <param index="0">
              <value>
                <![CDATA[Sara]]>
              </value>
            </param>
            <param index="1">
              <value>
                <![CDATA[1500.0]]>
              </value>
            </param>
          </params>
          <reporter-output>
          </reporter-output>
        </test-method> <!-- accountCreationTest -->
        <test-method status="PASS" signature="accountCreationTest(java.lang.String, double)[pri:0, instance:com.csscorp.bankapp.test.BankAppTest@32709393]" name="accountCreationTest" duration-ms="8" started-at="2021-05-07T14:29:07 IST" data-provider="accountsTestData" finished-at="2021-05-07T14:29:07 IST">
          <params>
            <param index="0">
              <value>
                <![CDATA[Ram]]>
              </value>
            </param>
            <param index="1">
              <value>
                <![CDATA[100.0]]>
              </value>
            </param>
          </params>
          <reporter-output>
          </reporter-output>
        </test-method> <!-- accountCreationTest -->
        <test-method status="PASS" signature="ExceptionTest()[pri:0, instance:com.csscorp.bankapp.test.BankAppTest@32709393]" name="ExceptionTest" duration-ms="8" started-at="2021-05-07T14:29:07 IST" finished-at="2021-05-07T14:29:08 IST">
          <exception class="com.csscorp.bankapp.exception.AccountNotFoundException">
            <message>
              <![CDATA[custom error message]]>
            </message>
            <full-stacktrace>
              <![CDATA[com.csscorp.bankapp.exception.AccountNotFoundException: custom error message
at com.csscorp.bankapp.dto.Bank.checkAccount(Bank.java:103)
at com.csscorp.bankapp.test.BankAppTest.ExceptionTest(BankAppTest.java:53)
at sun.reflect.NativeMethodAccessorImpl.invoke0(Native Method)
at sun.reflect.NativeMethodAccessorImpl.invoke(Unknown Source)
at sun.reflect.DelegatingMethodAccessorImpl.invoke(Unknown Source)
at java.lang.reflect.Method.invoke(Unknown Source)
at org.testng.internal.MethodInvocationHelper.invokeMethod(MethodInvocationHelper.java:135)
at org.testng.internal.TestInvoker.invokeMethod(TestInvoker.java:598)
at org.testng.internal.TestInvoker.invokeTestMethod(TestInvoker.java:174)
at org.testng.internal.MethodRunner.runInSequence(MethodRunner.java:46)
at org.testng.internal.TestInvoker$MethodInvocationAgent.invoke(TestInvoker.java:821)
at org.testng.internal.TestInvoker.invokeTestMethods(TestInvoker.java:147)
at org.testng.internal.TestMethodWorker.invokeTestMethods(TestMethodWorker.java:146)
at org.testng.internal.TestMethodWorker.run(TestMethodWorker.java:128)
at java.util.ArrayList.forEach(Unknown Source)
at org.testng.TestRunner.privateRun(TestRunner.java:767)
at org.testng.TestRunner.run(TestRunner.java:588)
at org.testng.SuiteRunner.runTest(SuiteRunner.java:384)
at org.testng.SuiteRunner.runSequentially(SuiteRunner.java:378)
at org.testng.SuiteRunner.privateRun(SuiteRunner.java:337)
at org.testng.SuiteRunner.run(SuiteRunner.java:286)
at org.testng.SuiteRunnerWorker.runSuite(SuiteRunnerWorker.java:53)
at org.testng.SuiteRunnerWorker.run(SuiteRunnerWorker.java:96)
at org.testng.TestNG.runSuitesSequentially(TestNG.java:1214)
at org.testng.TestNG.runSuitesLocally(TestNG.java:1136)
at org.testng.TestNG.runSuites(TestNG.java:1066)
at org.testng.TestNG.run(TestNG.java:1034)
at org.testng.remote.AbstractRemoteTestNG.run(AbstractRemoteTestNG.java:115)
at org.testng.remote.RemoteTestNG.initAndRun(RemoteTestNG.java:251)
at org.testng.remote.RemoteTestNG.main(RemoteTestNG.java:77)
]]>
            </full-stacktrace>
          </exception> <!-- com.csscorp.bankapp.exception.AccountNotFoundException -->
          <reporter-output>
          </reporter-output>
        </test-method> <!-- ExceptionTest -->
        <test-method status="PASS" signature="ExceptionTest1()[pri:0, instance:com.csscorp.bankapp.test.BankAppTest@32709393]" name="ExceptionTest1" duration-ms="5" started-at="2021-05-07T14:29:08 IST" finished-at="2021-05-07T14:29:08 IST">
          <exception class="com.csscorp.bankapp.exception.InsufficientFundException">
            <message>
              <![CDATA[Insufficient fund in your account...!]]>
            </message>
            <full-stacktrace>
              <![CDATA[com.csscorp.bankapp.exception.InsufficientFundException: Insufficient fund in your account...!
at com.csscorp.bankapp.dto.Bank.withdraw(Bank.java:118)
at com.csscorp.bankapp.test.BankAppTest.ExceptionTest1(BankAppTest.java:59)
at sun.reflect.NativeMethodAccessorImpl.invoke0(Native Method)
at sun.reflect.NativeMethodAccessorImpl.invoke(Unknown Source)
at sun.reflect.DelegatingMethodAccessorImpl.invoke(Unknown Source)
at java.lang.reflect.Method.invoke(Unknown Source)
at org.testng.internal.MethodInvocationHelper.invokeMethod(MethodInvocationHelper.java:135)
at org.testng.internal.TestInvoker.invokeMethod(TestInvoker.java:598)
at org.testng.internal.TestInvoker.invokeTestMethod(TestInvoker.java:174)
at org.testng.internal.MethodRunner.runInSequence(MethodRunner.java:46)
at org.testng.internal.TestInvoker$MethodInvocationAgent.invoke(TestInvoker.java:821)
at org.testng.internal.TestInvoker.invokeTestMethods(TestInvoker.java:147)
at org.testng.internal.TestMethodWorker.invokeTestMethods(TestMethodWorker.java:146)
at org.testng.internal.TestMethodWorker.run(TestMethodWorker.java:128)
at java.util.ArrayList.forEach(Unknown Source)
at org.testng.TestRunner.privateRun(TestRunner.java:767)
at org.testng.TestRunner.run(TestRunner.java:588)
at org.testng.SuiteRunner.runTest(SuiteRunner.java:384)
at org.testng.SuiteRunner.runSequentially(SuiteRunner.java:378)
at org.testng.SuiteRunner.privateRun(SuiteRunner.java:337)
at org.testng.SuiteRunner.run(SuiteRunner.java:286)
at org.testng.SuiteRunnerWorker.runSuite(SuiteRunnerWorker.java:53)
at org.testng.SuiteRunnerWorker.run(SuiteRunnerWorker.java:96)
at org.testng.TestNG.runSuitesSequentially(TestNG.java:1214)
at org.testng.TestNG.runSuitesLocally(TestNG.java:1136)
at org.testng.TestNG.runSuites(TestNG.java:1066)
at org.testng.TestNG.run(TestNG.java:1034)
at org.testng.remote.AbstractRemoteTestNG.run(AbstractRemoteTestNG.java:115)
at org.testng.remote.RemoteTestNG.initAndRun(RemoteTestNG.java:251)
at org.testng.remote.RemoteTestNG.main(RemoteTestNG.java:77)
]]>
            </full-stacktrace>
          </exception> <!-- com.csscorp.bankapp.exception.InsufficientFundException -->
          <reporter-output>
          </reporter-output>
        </test-method> <!-- ExceptionTest1 -->
        <test-method status="FAIL" signature="withdrawTest(java.lang.String, double)[pri:0, instance:com.csscorp.bankapp.test.BankAppTest@32709393]" name="withdrawTest" duration-ms="3" started-at="2021-05-07T14:29:08 IST" data-provider="withdrawTestData" depends-on-methods="com.csscorp.bankapp.test.BankAppTest.accountCreationTest" finished-at="2021-05-07T14:29:08 IST">
          <params>
            <param index="0">
              <value>
                <![CDATA[1001]]>
              </value>
            </param>
            <param index="1">
              <value>
                <![CDATA[500.0]]>
              </value>
            </param>
          </params>
          <exception class="java.lang.AssertionError">
            <message>
              <![CDATA[expected [false] but found [true]]]>
            </message>
            <full-stacktrace>
              <![CDATA[java.lang.AssertionError: expected [false] but found [true]
at org.testng.Assert.fail(Assert.java:97)
at org.testng.Assert.assertEqualsImpl(Assert.java:136)
at org.testng.Assert.assertEquals(Assert.java:118)
at org.testng.Assert.assertEquals(Assert.java:751)
at org.testng.Assert.assertEquals(Assert.java:761)
at com.csscorp.bankapp.test.BankAppTest.withdrawTest(BankAppTest.java:44)
at sun.reflect.NativeMethodAccessorImpl.invoke0(Native Method)
at sun.reflect.NativeMethodAccessorImpl.invoke(Unknown Source)
at sun.reflect.DelegatingMethodAccessorImpl.invoke(Unknown Source)
at java.lang.reflect.Method.invoke(Unknown Source)
at org.testng.internal.MethodInvocationHelper.invokeMethod(MethodInvocationHelper.java:135)
at org.testng.internal.TestInvoker.invokeMethod(TestInvoker.java:598)
at org.testng.internal.TestInvoker.invokeTestMethod(TestInvoker.java:174)
at org.testng.internal.MethodRunner.runInSequence(MethodRunner.java:46)
at org.testng.internal.TestInvoker$MethodInvocationAgent.invoke(TestInvoker.java:821)
at org.testng.internal.TestInvoker.invokeTestMethods(TestInvoker.java:147)
at org.testng.internal.TestMethodWorker.invokeTestMethods(TestMethodWorker.java:146)
at org.testng.internal.TestMethodWorker.run(TestMethodWorker.java:128)
at java.util.ArrayList.forEach(Unknown Source)
at org.testng.TestRunner.privateRun(TestRunner.java:767)
at org.testng.TestRunner.run(TestRunner.java:588)
at org.testng.SuiteRunner.runTest(SuiteRunner.java:384)
at org.testng.SuiteRunner.runSequentially(SuiteRunner.java:378)
at org.testng.SuiteRunner.privateRun(SuiteRunner.java:337)
at org.testng.SuiteRunner.run(SuiteRunner.java:286)
at org.testng.SuiteRunnerWorker.runSuite(SuiteRunnerWorker.java:53)
at org.testng.SuiteRunnerWorker.run(SuiteRunnerWorker.java:96)
at org.testng.TestNG.runSuitesSequentially(TestNG.java:1214)
at org.testng.TestNG.runSuitesLocally(TestNG.java:1136)
at org.testng.TestNG.runSuites(TestNG.java:1066)
at org.testng.TestNG.run(TestNG.java:1034)
at org.testng.remote.AbstractRemoteTestNG.run(AbstractRemoteTestNG.java:115)
at org.testng.remote.RemoteTestNG.initAndRun(RemoteTestNG.java:251)
at org.testng.remote.RemoteTestNG.main(RemoteTestNG.java:77)
]]>
            </full-stacktrace>
          </exception> <!-- java.lang.AssertionError -->
          <reporter-output>
          </reporter-output>
        </test-method> <!-- withdrawTest -->
        <test-method status="FAIL" signature="withdrawTest(java.lang.String, double)[pri:0, instance:com.csscorp.bankapp.test.BankAppTest@32709393]" name="withdrawTest" duration-ms="8" started-at="2021-05-07T14:29:08 IST" data-provider="withdrawTestData" depends-on-methods="com.csscorp.bankapp.test.BankAppTest.accountCreationTest" finished-at="2021-05-07T14:29:08 IST">
          <params>
            <param index="0">
              <value>
                <![CDATA[1002]]>
              </value>
            </param>
            <param index="1">
              <value>
                <![CDATA[2000.0]]>
              </value>
            </param>
          </params>
          <exception class="java.lang.AssertionError">
            <message>
              <![CDATA[expected [false] but found [true]]]>
            </message>
            <full-stacktrace>
              <![CDATA[java.lang.AssertionError: expected [false] but found [true]
at org.testng.Assert.fail(Assert.java:97)
at org.testng.Assert.assertEqualsImpl(Assert.java:136)
at org.testng.Assert.assertEquals(Assert.java:118)
at org.testng.Assert.assertEquals(Assert.java:751)
at org.testng.Assert.assertEquals(Assert.java:761)
at com.csscorp.bankapp.test.BankAppTest.withdrawTest(BankAppTest.java:44)
at sun.reflect.NativeMethodAccessorImpl.invoke0(Native Method)
at sun.reflect.NativeMethodAccessorImpl.invoke(Unknown Source)
at sun.reflect.DelegatingMethodAccessorImpl.invoke(Unknown Source)
at java.lang.reflect.Method.invoke(Unknown Source)
at org.testng.internal.MethodInvocationHelper.invokeMethod(MethodInvocationHelper.java:135)
at org.testng.internal.TestInvoker.invokeMethod(TestInvoker.java:598)
at org.testng.internal.TestInvoker.invokeTestMethod(TestInvoker.java:174)
at org.testng.internal.MethodRunner.runInSequence(MethodRunner.java:46)
at org.testng.internal.TestInvoker$MethodInvocationAgent.invoke(TestInvoker.java:821)
at org.testng.internal.TestInvoker.invokeTestMethods(TestInvoker.java:147)
at org.testng.internal.TestMethodWorker.invokeTestMethods(TestMethodWorker.java:146)
at org.testng.internal.TestMethodWorker.run(TestMethodWorker.java:128)
at java.util.ArrayList.forEach(Unknown Source)
at org.testng.TestRunner.privateRun(TestRunner.java:767)
at org.testng.TestRunner.run(TestRunner.java:588)
at org.testng.SuiteRunner.runTest(SuiteRunner.java:384)
at org.testng.SuiteRunner.runSequentially(SuiteRunner.java:378)
at org.testng.SuiteRunner.privateRun(SuiteRunner.java:337)
at org.testng.SuiteRunner.run(SuiteRunner.java:286)
at org.testng.SuiteRunnerWorker.runSuite(SuiteRunnerWorker.java:53)
at org.testng.SuiteRunnerWorker.run(SuiteRunnerWorker.java:96)
at org.testng.TestNG.runSuitesSequentially(TestNG.java:1214)
at org.testng.TestNG.runSuitesLocally(TestNG.java:1136)
at org.testng.TestNG.runSuites(TestNG.java:1066)
at org.testng.TestNG.run(TestNG.java:1034)
at org.testng.remote.AbstractRemoteTestNG.run(AbstractRemoteTestNG.java:115)
at org.testng.remote.RemoteTestNG.initAndRun(RemoteTestNG.java:251)
at org.testng.remote.RemoteTestNG.main(RemoteTestNG.java:77)
]]>
            </full-stacktrace>
          </exception> <!-- java.lang.AssertionError -->
          <reporter-output>
          </reporter-output>
        </test-method> <!-- withdrawTest -->
        <test-method status="FAIL" signature="withdrawTest(java.lang.String, double)[pri:0, instance:com.csscorp.bankapp.test.BankAppTest@32709393]" name="withdrawTest" duration-ms="3" started-at="2021-05-07T14:29:08 IST" data-provider="withdrawTestData" depends-on-methods="com.csscorp.bankapp.test.BankAppTest.accountCreationTest" finished-at="2021-05-07T14:29:08 IST">
          <params>
            <param index="0">
              <value>
                <![CDATA[1003]]>
              </value>
            </param>
            <param index="1">
              <value>
                <![CDATA[500.0]]>
              </value>
            </param>
          </params>
          <exception class="java.lang.AssertionError">
            <message>
              <![CDATA[expected [false] but found [true]]]>
            </message>
            <full-stacktrace>
              <![CDATA[java.lang.AssertionError: expected [false] but found [true]
at org.testng.Assert.fail(Assert.java:97)
at org.testng.Assert.assertEqualsImpl(Assert.java:136)
at org.testng.Assert.assertEquals(Assert.java:118)
at org.testng.Assert.assertEquals(Assert.java:751)
at org.testng.Assert.assertEquals(Assert.java:761)
at com.csscorp.bankapp.test.BankAppTest.withdrawTest(BankAppTest.java:44)
at sun.reflect.NativeMethodAccessorImpl.invoke0(Native Method)
at sun.reflect.NativeMethodAccessorImpl.invoke(Unknown Source)
at sun.reflect.DelegatingMethodAccessorImpl.invoke(Unknown Source)
at java.lang.reflect.Method.invoke(Unknown Source)
at org.testng.internal.MethodInvocationHelper.invokeMethod(MethodInvocationHelper.java:135)
at org.testng.internal.TestInvoker.invokeMethod(TestInvoker.java:598)
at org.testng.internal.TestInvoker.invokeTestMethod(TestInvoker.java:174)
at org.testng.internal.MethodRunner.runInSequence(MethodRunner.java:46)
at org.testng.internal.TestInvoker$MethodInvocationAgent.invoke(TestInvoker.java:821)
at org.testng.internal.TestInvoker.invokeTestMethods(TestInvoker.java:147)
at org.testng.internal.TestMethodWorker.invokeTestMethods(TestMethodWorker.java:146)
at org.testng.internal.TestMethodWorker.run(TestMethodWorker.java:128)
at java.util.ArrayList.forEach(Unknown Source)
at org.testng.TestRunner.privateRun(TestRunner.java:767)
at org.testng.TestRunner.run(TestRunner.java:588)
at org.testng.SuiteRunner.runTest(SuiteRunner.java:384)
at org.testng.SuiteRunner.runSequentially(SuiteRunner.java:378)
at org.testng.SuiteRunner.privateRun(SuiteRunner.java:337)
at org.testng.SuiteRunner.run(SuiteRunner.java:286)
at org.testng.SuiteRunnerWorker.runSuite(SuiteRunnerWorker.java:53)
at org.testng.SuiteRunnerWorker.run(SuiteRunnerWorker.java:96)
at org.testng.TestNG.runSuitesSequentially(TestNG.java:1214)
at org.testng.TestNG.runSuitesLocally(TestNG.java:1136)
at org.testng.TestNG.runSuites(TestNG.java:1066)
at org.testng.TestNG.run(TestNG.java:1034)
at org.testng.remote.AbstractRemoteTestNG.run(AbstractRemoteTestNG.java:115)
at org.testng.remote.RemoteTestNG.initAndRun(RemoteTestNG.java:251)
at org.testng.remote.RemoteTestNG.main(RemoteTestNG.java:77)
]]>
            </full-stacktrace>
          </exception> <!-- java.lang.AssertionError -->
          <reporter-output>
          </reporter-output>
        </test-method> <!-- withdrawTest -->
      </class> <!-- com.csscorp.bankapp.test.BankAppTest -->
    </test> <!-- Default test -->
  </suite> <!-- Default suite -->
</testng-results>
